2018-04-06 21:25:20,435 ERROR: Exception on /user/15922423170 [GET] [in /home/jeff/.virtualenvs/flask_blog/lib/python3.5/site-packages/flask/app.py:1560]
Traceback (most recent call last):
  File "/home/jeff/.virtualenvs/flask_blog/lib/python3.5/site-packages/sqlalchemy/engine/base.py", line 1193, in _execute_context
    context)
  File "/home/jeff/.virtualenvs/flask_blog/lib/python3.5/site-packages/sqlalchemy/engine/default.py", line 507, in do_execute
    cursor.execute(statement, parameters)
  File "/home/jeff/.virtualenvs/flask_blog/lib/python3.5/site-packages/cymysql/cursors.py", line 133, in execute
    self.errorhandler(exc, value)
  File "/home/jeff/.virtualenvs/flask_blog/lib/python3.5/site-packages/cymysql/cursors.py", line 35, in errorhandler
    self.connection.errorhandler(self, errorclass, errorvalue)
  File "/home/jeff/.virtualenvs/flask_blog/lib/python3.5/site-packages/cymysql/connections.py", line 118, in errorhandler
    raise errorvalue
  File "/home/jeff/.virtualenvs/flask_blog/lib/python3.5/site-packages/cymysql/cursors.py", line 128, in execute
    self._query(query)
  File "/home/jeff/.virtualenvs/flask_blog/lib/python3.5/site-packages/cymysql/cursors.py", line 238, in _query
    conn.query(q)
  File "/home/jeff/.virtualenvs/flask_blog/lib/python3.5/site-packages/cymysql/connections.py", line 345, in query
    self._result = MySQLResult(self)
  File "/home/jeff/.virtualenvs/flask_blog/lib/python3.5/site-packages/cymysql/packet.py", line 260, in __init__
    self.first_packet = MysqlPacket(self.connection)
  File "/home/jeff/.virtualenvs/flask_blog/lib/python3.5/site-packages/cymysql/packet.py", line 67, in __init__
    raise_mysql_exception(self.__data)
  File "/home/jeff/.virtualenvs/flask_blog/lib/python3.5/site-packages/cymysql/err.py", line 142, in raise_mysql_exception
    _check_mysql_exception(errinfo)
  File "/home/jeff/.virtualenvs/flask_blog/lib/python3.5/site-packages/cymysql/err.py", line 135, in _check_mysql_exception
    raise errorclass(errno,errorvalue)
cymysql.err.ProgrammingError: (1146, "Table 'flaskdev.followers' doesn't exist")

The above exception was the direct cause of the following exception:

Traceback (most recent call last):
  File "/home/jeff/.virtualenvs/flask_blog/lib/python3.5/site-packages/flask/app.py", line 1982, in wsgi_app
    response = self.full_dispatch_request()
  File "/home/jeff/.virtualenvs/flask_blog/lib/python3.5/site-packages/flask/app.py", line 1614, in full_dispatch_request
    rv = self.handle_user_exception(e)
  File "/home/jeff/.virtualenvs/flask_blog/lib/python3.5/site-packages/flask/app.py", line 1517, in handle_user_exception
    reraise(exc_type, exc_value, tb)
  File "/home/jeff/.virtualenvs/flask_blog/lib/python3.5/site-packages/flask/_compat.py", line 33, in reraise
    raise value
  File "/home/jeff/.virtualenvs/flask_blog/lib/python3.5/site-packages/flask/app.py", line 1612, in full_dispatch_request
    rv = self.dispatch_request()
  File "/home/jeff/.virtualenvs/flask_blog/lib/python3.5/site-packages/flask/app.py", line 1598, in dispatch_request
    return self.view_functions[rule.endpoint](**req.view_args)
  File "/home/jeff/.virtualenvs/flask_blog/lib/python3.5/site-packages/flask_login/utils.py", line 261, in decorated_view
    return func(*args, **kwargs)
  File "/home/jeff/PycharmProjects/flask_blog/app/routers.py", line 86, in user
    return render_template('user.html', user=user, posts=posts)
  File "/home/jeff/.virtualenvs/flask_blog/lib/python3.5/site-packages/flask/templating.py", line 134, in render_template
    context, ctx.app)
  File "/home/jeff/.virtualenvs/flask_blog/lib/python3.5/site-packages/flask/templating.py", line 116, in _render
    rv = template.render(context)
  File "/home/jeff/.virtualenvs/flask_blog/lib/python3.5/site-packages/jinja2/environment.py", line 1008, in render
    return self.environment.handle_exception(exc_info, True)
  File "/home/jeff/.virtualenvs/flask_blog/lib/python3.5/site-packages/jinja2/environment.py", line 780, in handle_exception
    reraise(exc_type, exc_value, tb)
  File "/home/jeff/.virtualenvs/flask_blog/lib/python3.5/site-packages/jinja2/_compat.py", line 37, in reraise
    raise value.with_traceback(tb)
  File "/home/jeff/PycharmProjects/flask_blog/app/templates/user.html", line 1, in top-level template code
    {% extends "base.html" %}
  File "/home/jeff/PycharmProjects/flask_blog/app/templates/base.html", line 30, in top-level template code
    {% block content %}{% endblock %}
  File "/home/jeff/PycharmProjects/flask_blog/app/templates/user.html", line 11, in block "content"
    <p>{{ user.followers.count() }} followers, {{ user.followed.count() }} following.</p>
  File "/home/jeff/.virtualenvs/flask_blog/lib/python3.5/site-packages/sqlalchemy/orm/dynamic.py", line 265, in count
    return self._clone(sess).count()
  File "/home/jeff/.virtualenvs/flask_blog/lib/python3.5/site-packages/sqlalchemy/orm/query.py", line 3124, in count
    return self.from_self(col).scalar()
  File "/home/jeff/.virtualenvs/flask_blog/lib/python3.5/site-packages/sqlalchemy/orm/query.py", line 2877, in scalar
    ret = self.one()
  File "/home/jeff/.virtualenvs/flask_blog/lib/python3.5/site-packages/sqlalchemy/orm/query.py", line 2848, in one
    ret = self.one_or_none()
  File "/home/jeff/.virtualenvs/flask_blog/lib/python3.5/site-packages/sqlalchemy/orm/query.py", line 2818, in one_or_none
    ret = list(self)
  File "/home/jeff/.virtualenvs/flask_blog/lib/python3.5/site-packages/sqlalchemy/orm/query.py", line 2889, in __iter__
    return self._execute_and_instances(context)
  File "/home/jeff/.virtualenvs/flask_blog/lib/python3.5/site-packages/sqlalchemy/orm/query.py", line 2912, in _execute_and_instances
    result = conn.execute(querycontext.statement, self._params)
  File "/home/jeff/.virtualenvs/flask_blog/lib/python3.5/site-packages/sqlalchemy/engine/base.py", line 948, in execute
    return meth(self, multiparams, params)
  File "/home/jeff/.virtualenvs/flask_blog/lib/python3.5/site-packages/sqlalchemy/sql/elements.py", line 269, in _execute_on_connection
    return connection._execute_clauseelement(self, multiparams, params)
  File "/home/jeff/.virtualenvs/flask_blog/lib/python3.5/site-packages/sqlalchemy/engine/base.py", line 1060, in _execute_clauseelement
    compiled_sql, distilled_params
  File "/home/jeff/.virtualenvs/flask_blog/lib/python3.5/site-packages/sqlalchemy/engine/base.py", line 1200, in _execute_context
    context)
  File "/home/jeff/.virtualenvs/flask_blog/lib/python3.5/site-packages/sqlalchemy/engine/base.py", line 1413, in _handle_dbapi_exception
    exc_info
  File "/home/jeff/.virtualenvs/flask_blog/lib/python3.5/site-packages/sqlalchemy/util/compat.py", line 203, in raise_from_cause
    reraise(type(exception), exception, tb=exc_tb, cause=cause)
  File "/home/jeff/.virtualenvs/flask_blog/lib/python3.5/site-packages/sqlalchemy/util/compat.py", line 186, in reraise
    raise value.with_traceback(tb)
  File "/home/jeff/.virtualenvs/flask_blog/lib/python3.5/site-packages/sqlalchemy/engine/base.py", line 1193, in _execute_context
    context)
  File "/home/jeff/.virtualenvs/flask_blog/lib/python3.5/site-packages/sqlalchemy/engine/default.py", line 507, in do_execute
    cursor.execute(statement, parameters)
  File "/home/jeff/.virtualenvs/flask_blog/lib/python3.5/site-packages/cymysql/cursors.py", line 133, in execute
    self.errorhandler(exc, value)
  File "/home/jeff/.virtualenvs/flask_blog/lib/python3.5/site-packages/cymysql/cursors.py", line 35, in errorhandler
    self.connection.errorhandler(self, errorclass, errorvalue)
  File "/home/jeff/.virtualenvs/flask_blog/lib/python3.5/site-packages/cymysql/connections.py", line 118, in errorhandler
    raise errorvalue
  File "/home/jeff/.virtualenvs/flask_blog/lib/python3.5/site-packages/cymysql/cursors.py", line 128, in execute
    self._query(query)
  File "/home/jeff/.virtualenvs/flask_blog/lib/python3.5/site-packages/cymysql/cursors.py", line 238, in _query
    conn.query(q)
  File "/home/jeff/.virtualenvs/flask_blog/lib/python3.5/site-packages/cymysql/connections.py", line 345, in query
    self._result = MySQLResult(self)
  File "/home/jeff/.virtualenvs/flask_blog/lib/python3.5/site-packages/cymysql/packet.py", line 260, in __init__
    self.first_packet = MysqlPacket(self.connection)
  File "/home/jeff/.virtualenvs/flask_blog/lib/python3.5/site-packages/cymysql/packet.py", line 67, in __init__
    raise_mysql_exception(self.__data)
  File "/home/jeff/.virtualenvs/flask_blog/lib/python3.5/site-packages/cymysql/err.py", line 142, in raise_mysql_exception
    _check_mysql_exception(errinfo)
  File "/home/jeff/.virtualenvs/flask_blog/lib/python3.5/site-packages/cymysql/err.py", line 135, in _check_mysql_exception
    raise errorclass(errno,errorvalue)
sqlalchemy.exc.ProgrammingError: (cymysql.err.ProgrammingError) (1146, "Table 'flaskdev.followers' doesn't exist") [SQL: 'SELECT count(*) AS count_1 \nFROM (SELECT user.id AS user_id, user.username AS user_username, user.email AS user_email, user.password_hash AS user_password_hash, user.about_me AS user_about_me, user.last_seen AS user_last_seen \nFROM user, followers \nWHERE followers.followed_id = %s AND followers.follower_id = user.id) AS anon_1'] [parameters: (2,)] (Background on this error at: http://sqlalche.me/e/f405)
2018-04-06 21:33:45,011 INFO: Microblog startup [in /home/jeff/PycharmProjects/flask_blog/app/__init__.py:46]
2018-04-06 21:34:37,214 INFO: Microblog startup [in /home/jeff/PycharmProjects/flask_blog/app/__init__.py:46]
2018-04-06 21:34:58,472 INFO: Microblog startup [in /home/jeff/PycharmProjects/flask_blog/app/__init__.py:46]
2018-04-06 21:35:23,108 INFO: Microblog startup [in /home/jeff/PycharmProjects/flask_blog/app/__init__.py:46]
2018-04-06 21:36:09,867 INFO: Microblog startup [in /home/jeff/PycharmProjects/flask_blog/app/__init__.py:46]
2018-04-06 21:36:14,395 INFO: Microblog startup [in /home/jeff/PycharmProjects/flask_blog/app/__init__.py:46]
2018-04-06 21:36:24,769 INFO: Microblog startup [in /home/jeff/PycharmProjects/flask_blog/app/__init__.py:46]
2018-04-06 21:36:36,505 INFO: Microblog startup [in /home/jeff/PycharmProjects/flask_blog/app/__init__.py:46]
